
Epoch 1/30
wandb: WARNING The save_model argument by default saves the model in the HDF5 format that cannot save custom objects like subclassed models and custom layers. This behavior will be deprecated in a future release in favor of the SavedModel format. Meanwhile, the HDF5 model is saved as W&B files and the SavedModel as W&B Artifacts.
Traceback (most recent call last):
  File "C:\Users\PAVILION 15-DW001LA\Documents\Tesis\CÃ³digos\RNAs\Red_Conv2D\Red_Conv2D.py", line 84, in <module>
    model.fit(x_trainv, y_trainv,
  File "C:\Users\PAVILION 15-DW001LA\miniconda3\lib\site-packages\wandb\integration\keras\keras.py", line 174, in new_v2
    return old_v2(*args, **kwargs)
  File "C:\Users\PAVILION 15-DW001LA\miniconda3\lib\site-packages\wandb\integration\keras\keras.py", line 174, in new_v2
    return old_v2(*args, **kwargs)
  File "C:\Users\PAVILION 15-DW001LA\miniconda3\lib\site-packages\wandb\integration\keras\keras.py", line 174, in new_v2
    return old_v2(*args, **kwargs)
  File "C:\Users\PAVILION 15-DW001LA\miniconda3\lib\site-packages\keras\utils\traceback_utils.py", line 67, in error_handler
    raise e.with_traceback(filtered_tb) from None
  File "C:\Users\PAVILION 15-DW001LA\miniconda3\lib\site-packages\tensorflow\python\framework\func_graph.py", line 1129, in autograph_handler
    raise e.ag_error_metadata.to_exception(e)
ValueError: in user code:
    File "C:\Users\PAVILION 15-DW001LA\miniconda3\lib\site-packages\keras\engine\training.py", line 878, in train_function  *
        return step_function(self, iterator)
    File "C:\Users\PAVILION 15-DW001LA\miniconda3\lib\site-packages\keras\engine\training.py", line 867, in step_function  **
        outputs = model.distribute_strategy.run(run_step, args=(data,))
    File "C:\Users\PAVILION 15-DW001LA\miniconda3\lib\site-packages\keras\engine\training.py", line 860, in run_step  **
        outputs = model.train_step(data)
    File "C:\Users\PAVILION 15-DW001LA\miniconda3\lib\site-packages\keras\engine\training.py", line 808, in train_step
        y_pred = self(x, training=True)
    File "C:\Users\PAVILION 15-DW001LA\miniconda3\lib\site-packages\keras\utils\traceback_utils.py", line 67, in error_handler
        raise e.with_traceback(filtered_tb) from None
    File "C:\Users\PAVILION 15-DW001LA\miniconda3\lib\site-packages\keras\engine\input_spec.py", line 263, in assert_input_compatibility
        raise ValueError(f'Input {input_index} of layer "{layer_name}" is '
    ValueError: Input 0 of layer "sequential" is incompatible with the layer: expected shape=(None, 784, 100, 2), found shape=(None, 100, 2)